Workbook
Name \0: #REF!
Name \0: #REF!
Name \0: #REF!
Name \0: #REF!
Name \0: #REF!
Name \00: #REF!
Name \00: #REF!
Name \00: #REF!
Name \00: #REF!
Name \00: #REF!
Name \44333: #REF!
Name \44333: #REF!
Name \44333: #REF!
Name \44333: #REF!
Name \44333: #REF!
Name \a: #REF!
Name \a: #REF!
Name \a: #REF!
Name \a: #REF!
Name \a: #REF!
Name \add9a: #REF!
Name \add9a: #REF!
Name \add9a: #REF!
Name \add9a: #REF!
Name \add9a: #REF!
Name \b: #REF!
Name \b: #REF!
Name \b: #REF!
Name \b: #REF!
Name \b: #REF!
Name \B1: #REF!
Name \B1: #REF!
Name \B1: #REF!
Name \B1: #REF!
Name \B10: #REF!
Name \B10: #REF!
Name \B10: #REF!
Name \B10: #REF!
Name \B11: #REF!
Name \B11: #REF!
Name \B11: #REF!
Name \B11: #REF!
Name \B12: #REF!
Name \B12: #REF!
Name \B12: #REF!
Name \B13: #REF!
Name \B13: #REF!
Name \B13: #REF!
Name \B14: #REF!
Name \B14: #REF!
Name \B14: #REF!
Name \B2: #REF!
Name \B2: #REF!
Name \B2: #REF!
Name \B3: #REF!
Name \B3: #REF!
Name \B3: #REF!
Name \B4: #REF!
Name \B4: #REF!
Name \B4: #REF!

Sheet Resumen Ejecutivo
C2: PROYECTO: | D2: CONSTRUCCIÓN DE 50 PILAS DE CONCRETO ARMADO PARA PMI'S EN EL ESTADO DE TAMAULIPAS (TAMPICO Y MANTE)
C3: CLIENTE: | D3: SYM KABAT | K3: Fecha
C4: RESUMEN EJECUTIVO | K4: =TODAY() -> 46076
B5: 1. INFORMACIÓN DE PROYECTO
B7: Fecha Presentación | C7: Fecha Adjudicación | F7: Inicio de Obra | K7: Público/ Privado
B8: 45809 | C8: 45817 | F8: 07.07.2025 | J8: Tipo Licitación: | K8: PRIVADO
B10: Contrato S/ IVA | C10: Contrato C/ IVA | F10: Anticipo s/ IVA | G10: Anticipo c/ IVA | J10: Personal Estratégico: | K10: N.A.
B11: =Producción!$I$9 -> 7818391.5 | C11: =B11*1.16 -> 9069334.1 | F11: ='Control Certificación'!$H$13 -> 929236.37 | G11: =F11*1.16 -> 1077914.2 | J11: Contacto:
B13: Fianza Anticipo | D13: 45689 | J13: Teléfono:
B14: Monto Afianzado | C14: Costo Poliza | D14: Vigencia | F14: Fin Contractual | G14: Fin Previsto
B17: Fianza Cumplimiento | D17: 45799 | F17: Fianza Vicios Ocultos
B18: Monto Afianzado | C18: Costo Fianza | D18: Vigencia | F18: Importe | G18: Vigencia
B21: Seguro CAR (Todo Riesgo de Construcción) | F21: Seguro Responsabilidad Civil
B22: Monto Afianzado | C22: Costo Fianza | D22: Vigencia | F22: Importe | G22: Vigencia
B25: 2. SITUACIÓN ACTUAL DE OBRA
B27: Anticipo | J27: =CONCATENATE("Actualizado hasta ",VLOOKUP(MAX(Certificacion[FECHA FACTURA]),Certificacion[[FECHA FACTURA]:[PERIODO Imp.]],2)) -> Actualizado hasta DIC 2025 Q1
B28: Anticipo S/Iva | C28: Amort. S/Iva acum. | D28: Amort. S/Iva pendiente | F28: Anticipo Liquido | G28: Amort. Líquida acum. | I28: Amort. Líquida pendiente
B29: ='Control Certificación'!$K$6 -> 929236.37 | C29: ='Control Certificación'!$O$6 -> 0 | D29: =B29-C29 -> 929236.37 | F29: ='Control Certificación'!$K$6*1.16 -> 1077914.2 | G29: ='Control Certificación'!$O$6*1.16 -> 0 | I29: =F29-G29 -> 1077914.2
B31: Certificación | H31: =IFERROR(CONCATENATE("Actualizado hasta ",VLOOKUP(MAX(Certificacion[FECHA FACTURA]),Certificacion[[FECHA FACTURA]:[PERIODO Imp.]],2)),"$") -> Actualizado hasta DIC 2025 Q1
B32: Certificación S/ Iva | C32: Adeudo s/ Iva | F32: Certificación Líquida | G32: Adeudo Líquido de cobro | J32: Días Vencimiento fra. más atrasada
B33: =SUMIF(Certificacion[APLICA],"ESTIMACION",Certificacion[IMPORTE]) -> 5685234.1 | C33: =SUMIFS(Certificacion[IMPORTE],Certificacion[APLICA],"ESTIMACION",Certificacion[FECHA DE PAGO],"") -> 5685234.1 | F33: =SUMIF(Certificacion[APLICA],"ESTIMACION",Certificacion[LIQUIDO A PAGAR]) -> 6594871.6 | G33: =SUMIFS(Certificacion[LIQUIDO A PAGAR],Certificacion[APLICA],"ESTIMACION",Certificacion[FECHA DE PAGO],"") -> 6594871.6 | J33: ='Control Certificación'!$R$8 -> 192 días
B35: Retenciones por fondo de garantía | H35: =IFERROR(CONCATENATE("Actualizado hasta ",VLOOKUP(MAX(Certificacion[FECHA FACTURA]),Certificacion[[FECHA FACTURA]:[PERIODO Imp.]],2)),"$") -> Actualizado hasta DIC 2025 Q1
B36: Retención acum. S/ Iva | C36: Pagos acum. S/ Iva | F36: Ret. Acum. Líquida | G36: Pago Acum. Líquido
B37: =SUMIF(Certificacion[APLICA],"RETENCION 5%",Certificacion[OTROS (FONDO GARANTÍA)]) -> 0 | C37: ='Resumen Ejecutivo'!B37-(SUMIFS(Certificacion[OTROS (FONDO GARANTÍA)],Certificacion[APLICA],"RETENCION 5%",Certificacion[FECHA DE PAGO],"")) -> 0 | F37: =SUMIF(Certificacion[APLICA],"RETENCION 5%",'Control Certificación'!$Q$15:$Q$95)*-1 -> 0 | G37: =F37-(SUMIFS('Control Certificación'!$Q$15:$Q$95,Certificacion[APLICA],"RETENCION 5%",Certificacion[FECHA DE PAGO],""))*-1 -> 0
B39: Producción | D39: =CONCATENATE("Actualizado hasta ",(HLOOKUP(MAX(Producción!#REF!),Producción!BN6:DI8,2))) -> #REF!
B40: Producción acumulada | C40: Producción Estimada | D40: Obra ejecutada no estimada
B41: =Producción!BL9 -> 5676539.1 | C41: =B33 -> 5685234.1 | D41: =B41-C41 -> -8694.988
B43: 3. ANÁLISIS TÉCNICO-ECONÓMICO DE LA OBRA
B45: Partidas principales por E7 | F45: Estudio | G45: Contrato | H45: Acumulado
F46: =F47+F51+F55 -> 0 | G46: =G47+G51+G55 -> 7740567.5 | H46: =H47+H51+H55 -> 5676539.1
B47: =Producción!E10 -> PILAS DE CIMENTACIÓN | F47: =F48-F49 -> 0 | G47: =G48-G49 -> 6371392.1 | H47: =H48-H49 -> 4698269
B48: Producción | G48: =Producción!I10 -> 6371392.1 | H48: =Producción!BL10 -> 4698269
B49: Costo Directo
B51: =Producción!E143 -> MECÁNICAS DE SUELOS Y TOPOGRAFÍAS | F51: =F52-F53 -> 0 | G51: =G52-G53 -> 991424.59 | H51: =H52-H53 -> 616735.43
B52: Producción | G52: =Producción!I143 -> 991424.59 | H52: =Producción!BL143 -> 616735.43
B53: Costo Directo
B55: =Producción!E254 -> SHELTER JIQUILPAN | F55: =F56-F57 -> 0 | G55: =G56-G57 -> 377750.82 | H55: =H56-H57 -> 361534.71
B56: Producción | G56: =Producción!I254 -> 377750.82 | H56: =Producción!BL254 -> 361534.71
B57: Costo Directo
B60: Resultado por familias | F60: Estudio | G60: ACTUAL Contrato | H60: Acumulado | J60: Pendiente | K60: Desvío
...

Sheet Imput
C3: CONTROL DE COSTOS | N3: Tipo de Cambio (MXN / USD): | P3: 20
C4: =CONCATENATE('Resumen Ejecutivo'!C2," ",'Resumen Ejecutivo'!D2) -> PROYECTO: CONSTRUCCIÓN DE 50 PILAS DE CONCRETO ARMADO PARA PMI'S EN EL ESTADO DE TAMAULIPAS (TAMPICO Y MANTE)
C5: =CONCATENATE('Resumen Ejecutivo'!C3," ",'Resumen Ejecutivo'!D3) -> CLIENTE: SYM KABAT | K5: Total C/COD IMPUT | L5: =Resultado!E13 -> 3533925.1 | N5: FECHA: | P5: =TODAY() -> 46076
B8: PERIODO Imp. | C8: C. Imp. | D8: Datos de Empresa | F8: Datos de Compra | P8: Datos Facturación | U8: CHEK LIST | V8: CUENTA CONTABLE | Y8: OBSERVACIONES | Z8: OBSERVACION ADICIONAL | AB8: Acreedor
D9: R.F.C. | E9: RAZON SOCIAL | F9: Descripcion concepto | G9: Cantidad | H9: Precio Unitario | I9: Sub total | J9: IVA | K9: Retención / Descuento | L9: Importe Neto | M9: Importe Neto por Factura | N9: Doc | O9: Tipo de Cambio USD | P9: Folio (UUID) o (SUA) | Q9: Folio | R9: Fecha | S9: Tipo de Pago | T9: Fecha de Pago (transferencias) | W9: SUBCUENTA
I10: =SUBTOTAL(9,Imput[Sub total]) -> 6463521.1 | J10: =SUBTOTAL(9,Imput[IVA]) -> 611525.37 | K10: =SUBTOTAL(9,Imput[Retención / IEPS / Descuento]) -> 17700.802 | L10: =SUBTOTAL(9,Imput[Importe Neto]) -> 7057345.7 | M10: =SUBTOTAL(9,Imput[Columna8]) -> 7057345.7
B11: PERIODO Imp. | C11: C. Imp. | D11: RFC | E11: RAZON SOCIAL | F11: Descripcion concepto | G11: Cantidad | H11: Precio Unitario | I11: Sub total | J11: IVA | K11: Retención / IEPS / Descuento | L11: Importe Neto | M11: Columna8 | N11: Documento | O11: Tipo de Cambio USD | P11: Folio (UUID) | Q11: Folio | R11: Fecha | S11: Tipo de Pago | T11: Estatus de Pago | U11: CHEK LIST | V11: Columna5 | W11: Columna6 | X11: Columna7 | Y11: Columna3 | Z11: Observaciones | AA11: Columna1 | AB11: Columna2
B12: JUN 2025 Q2 | C12: C3-5 | D12: ANA050518RL1 | E12: =IFERROR(IF(_xlfn.XLOOKUP(Imput[[#This Row],[RFC]],'Alta Proveedor'!D:D,'Alta Proveedor'!E:E)=0,"",_xlfn.XLOOKUP(Imput[[#This Row],[RFC]],'Alta Proveedor'!D:D,'Alta Proveedor'!E:E)),"") -> AEROENLACES NACIONALES (VUELOS) | F12: VUELOS - TARIFA AEREA PNR: PY4P6C | G12: 1 | H12: 2577.02 | I12: =Imput[[#This Row],[Cantidad]]*Imput[[#This Row],[Precio Unitario]] -> 2577.02 | J12: =Imput[[#This Row],[Sub total]]*0.159999 -> 412.32062 | K12: 0 | L12: =Imput[[#This Row],[Sub total]]+Imput[[#This Row],[IVA]]-Imput[[#This Row],[Retención / IEPS / Descuento]] -> 2989.3406 | M12: 4262.3446 | N12: Factura | P12: 858a58f4-390e-4a04-b8bc-7707d88b7d01 | Q12: B 130063376 | R12: 45686 | S12: 04.- TDC | V12: VIATICOS | W12: TRASLADO
B13: JUN 2025 Q2 | C13: C3-5 | D13: ANA050518RL1 | E13: =IFERROR(IF(_xlfn.XLOOKUP(Imput[[#This Row],[RFC]],'Alta Proveedor'!D:D,'Alta Proveedor'!E:E)=0,"",_xlfn.XLOOKUP(Imput[[#This Row],[RFC]],'Alta Proveedor'!D:D,'Alta Proveedor'!E:E)),"") -> AEROENLACES NACIONALES (VUELOS) | F13: VUELOS - SERVICIOS ADICIONALES | G13: 1 | H13: 14.15 | I13: =Imput[[#This Row],[Cantidad]]*Imput[[#This Row],[Precio Unitario]] -> 14.15 | J13: =Imput[[#This Row],[Sub total]]*0.159999 -> 2.2639859 | K13: 0 | L13: =Imput[[#This Row],[Sub total]]+Imput[[#This Row],[IVA]]-Imput[[#This Row],[Retención / IEPS / Descuento]] -> 16.413986 | M13: 0 | N13: Factura | P13: 858a58f4-390e-4a04-b8bc-7707d88b7d01 | Q13: B 130063376 | R13: 45686 | S13: 04.- TDC | V13: VIATICOS | W13: TRASLADO
B14: JUN 2025 Q2 | C14: C3-5 | D14: ANA050518RL1 | E14: =IFERROR(IF(_xlfn.XLOOKUP(Imput[[#This Row],[RFC]],'Alta Proveedor'!D:D,'Alta Proveedor'!E:E)=0,"",_xlfn.XLOOKUP(Imput[[#This Row],[RFC]],'Alta Proveedor'!D:D,'Alta Proveedor'!E:E)),"") -> AEROENLACES NACIONALES (VUELOS) | F14: VUELOS - CARGOS AEROPORTUARIOS | G14: 1 | H14: 1256.59 | I14: =Imput[[#This Row],[Cantidad]]*Imput[[#This Row],[Precio Unitario]] -> 1256.59 | J14: 0 | K14: 0 | L14: =Imput[[#This Row],[Sub total]]+Imput[[#This Row],[IVA]]-Imput[[#This Row],[Retención / IEPS / Descuento]] -> 1256.59 | M14: 0 | N14: Factura | P14: 858a58f4-390e-4a04-b8bc-7707d88b7d01 | Q14: B 130063376 | R14: 45686 | S14: 04.- TDC | V14: VIATICOS | W14: TRASLADO
B15: JUN 2025 Q2 | C15: C4-6 | D15: CAHE700209ATA | E15: =IFERROR(IF(_xlfn.XLOOKUP(Imput[[#This Row],[RFC]],'Alta Proveedor'!D:D,'Alta Proveedor'!E:E)=0,"",_xlfn.XLOOKUP(Imput[[#This Row],[RFC]],'Alta Proveedor'!D:D,'Alta Proveedor'!E:E)),"") -> ELVIA CABRERA HUERTA "MI PUEBLITO, MMM… QUE SABOR" (RESTAURANTE) | F15: RESTAURANTE - FAJIITA CON QUESO HARINA | G15: 1 | H15: 38.79 | I15: =Imput[[#This Row],[Cantidad]]*Imput[[#This Row],[Precio Unitario]] -> 38.79 | J15: =Imput[[#This Row],[Sub total]]*0.16 -> 6.2064 | K15: 0 | L15: =Imput[[#This Row],[Sub total]]+Imput[[#This Row],[IVA]]-Imput[[#This Row],[Retención / IEPS / Descuento]] -> 44.9964 | M15: 246.00584 | N15: Factura | P15: 273F2A11-F7FE-4321-8DCB-CE6BC96C18A1 | Q15: C3742 | R15: 45831 | S15: 28.- TDD | V15: VIATICOS | W15: ALIMENTOS
B16: JUN 2025 Q2 | C16: C4-6 | D16: CAHE700209ATA | E16: =IFERROR(IF(_xlfn.XLOOKUP(Imput[[#This Row],[RFC]],'Alta Proveedor'!D:D,'Alta Proveedor'!E:E)=0,"",_xlfn.XLOOKUP(Imput[[#This Row],[RFC]],'Alta Proveedor'!D:D,'Alta Proveedor'!E:E)),"") -> ELVIA CABRERA HUERTA "MI PUEBLITO, MMM… QUE SABOR" (RESTAURANTE) | F16: RESTAURANTE - HORCHATA 1 LITRO | G16: 1 | H16: 38.79 | I16: =Imput[[#This Row],[Cantidad]]*Imput[[#This Row],[Precio Unitario]] -> 38.79 | J16: =Imput[[#This Row],[Sub total]]*0.16 -> 6.2064 | K16: 0 | L16: =Imput[[#This Row],[Sub total]]+Imput[[#This Row],[IVA]]-Imput[[#This Row],[Retención / IEPS / Descuento]] -> 44.9964 | M16: 0 | N16: Factura | P16: 273F2A11-F7FE-4321-8DCB-CE6BC96C18A1 | Q16: C3742 | R16: 45831 | S16: 28.- TDD | V16: VIATICOS | W16: ALIMENTOS
B17: JUN 2025 Q2 | C17: C4-6 | D17: CAHE700209ATA | E17: =IFERROR(IF(_xlfn.XLOOKUP(Imput[[#This Row],[RFC]],'Alta Proveedor'!D:D,'Alta Proveedor'!E:E)=0,"",_xlfn.XLOOKUP(Imput[[#This Row],[RFC]],'Alta Proveedor'!D:D,'Alta Proveedor'!E:E)),"") -> ELVIA CABRERA HUERTA "MI PUEBLITO, MMM… QUE SABOR" (RESTAURANTE) | F17: RESTAURANTE - COCAS | G17: 1 | H17: 25.86 | I17: =Imput[[#This Row],[Cantidad]]*Imput[[#This Row],[Precio Unitario]] -> 25.86 | J17: =Imput[[#This Row],[Sub total]]*0.16 -> 4.1376 | K17: 0 | L17: =Imput[[#This Row],[Sub total]]+Imput[[#This Row],[IVA]]-Imput[[#This Row],[Retención / IEPS / Descuento]] -> 29.9976 | M17: 0 | N17: Factura | P17: 273F2A11-F7FE-4321-8DCB-CE6BC96C18A1 | Q17: C3742 | R17: 45831 | S17: 28.- TDD | V17: VIATICOS | W17: ALIMENTOS
B18: JUN 2025 Q2 | C18: C4-6 | D18: CAHE700209ATA | E18: =IFERROR(IF(_xlfn.XLOOKUP(Imput[[#This Row],[RFC]],'Alta Proveedor'!D:D,'Alta Proveedor'!E:E)=0,"",_xlfn.XLOOKUP(Imput[[#This Row],[RFC]],'Alta Proveedor'!D:D,'Alta Proveedor'!E:E)),"") -> ELVIA CABRERA HUERTA "MI PUEBLITO, MMM… QUE SABOR" (RESTAURANTE) | F18: RESTAURANTE - CHULETA CON QUESO HARINA | G18: 1 | H18: 36.21 | I18: =Imput[[#This Row],[Cantidad]]*Imput[[#This Row],[Precio Unitario]] -> 36.21 | J18: =Imput[[#This Row],[Sub total]]*0.16 -> 5.7936 | K18: 0 | L18: =Imput[[#This Row],[Sub total]]+Imput[[#This Row],[IVA]]-Imput[[#This Row],[Retención / IEPS / Descuento]] -> 42.0036 | M18: 0 | N18: Factura | P18: 273F2A11-F7FE-4321-8DCB-CE6BC96C18A1 | Q18: C3742 | R18: 45831 | S18: 28.- TDD | V18: VIATICOS | W18: ALIMENTOS
B19: JUN 2025 Q2 | C19: C4-6 | D19: CAHE700209ATA | E19: =IFERROR(IF(_xlfn.XLOOKUP(Imput[[#This Row],[RFC]],'Alta Proveedor'!D:D,'Alta Proveedor'!E:E)=0,"",_xlfn.XLOOKUP(Imput[[#This Row],[RFC]],'Alta Proveedor'!D:D,'Alta Proveedor'!E:E)),"") -> ELVIA CABRERA HUERTA "MI PUEBLITO, MMM… QUE SABOR" (RESTAURANTE) | F19: RESTAURANTE - CHULETA CON QUESO HARINA | G19: 2 | H19: 36.212 | I19: =Imput[[#This Row],[Cantidad]]*Imput[[#This Row],[Precio Unitario]] -> 72.424 | J19: =Imput[[#This Row],[Sub total]]*0.16 -> 11.58784 | K19: 0 | L19: =Imput[[#This Row],[Sub total]]+Imput[[#This Row],[IVA]]-Imput[[#This Row],[Retención / IEPS / Descuento]] -> 84.01184 | M19: 0 | N19: Factura | P19: 273F2A11-F7FE-4321-8DCB-CE6BC96C18A1 | Q19: C3742 | R19: 45831 | S19: 28.- TDD | V19: VIATICOS | W19: ALIMENTOS
B20: JUN 2025 Q2 | C20: C2-7 | D20: SSA010807N4A | E20: =IFERROR(IF(_xlfn.XLOOKUP(Imput[[#This Row],[RFC]],'Alta Proveedor'!D:D,'Alta Proveedor'!E:E)=0,"",_xlfn.XLOOKUP(Imput[[#This Row],[RFC]],'Alta Proveedor'!D:D,'Alta Proveedor'!E:E)),"") -> SERVICIO SAROGAR "NEXUM" (COMBUSTIBLES) | F20: COMBUSTIBLE - PREMIUM (2790780) | G20: 53.329913 | H20: 21.940725 | I20: =Imput[[#This Row],[Cantidad]]*Imput[[#This Row],[Precio Unitario]] -> 1170.097 | J20: 181.28 | K20: 0 | L20: =Imput[[#This Row],[Sub total]]+Imput[[#This Row],[IVA]]-Imput[[#This Row],[Retención / IEPS / Descuento]] -> 1351.377 | M20: 1351.377 | N20: Factura | P20: FC80EB46-3066-427F-8BC4-74B93B207014 | Q20: SSAFE - 85053 | R20: 45831 | S20: 04.- TDC | V20: COMBUSTIBLES | W20: GASOLINA
B21: JUN 2025 Q2 | C21: C4-6 | D21: POAJ841027D66 | E21: =IFERROR(IF(_xlfn.XLOOKUP(Imput[[#This Row],[RFC]],'Alta Proveedor'!D:D,'Alta Proveedor'!E:E)=0,"",_xlfn.XLOOKUP(Imput[[#This Row],[RFC]],'Alta Proveedor'!D:D,'Alta Proveedor'!E:E)),"") -> JONATHAN AZAEL PORTILLO ALEJO "EL MADERENSE MARISQUERIA" (RESTAURANTE) | F21: RESTAURANTE - CONSUMO DE ALIMENTOS Y BEBIDAS | G21: 1 | H21: =496.73+57 -> 553.73 | I21: =Imput[[#This Row],[Cantidad]]*Imput[[#This Row],[Precio Unitario]] -> 553.73 | J21: =(Imput[[#This Row],[Sub total]]-57)*0.16 -> 79.4768 | K21: 6.21 | L21: =Imput[[#This Row],[Sub total]]+Imput[[#This Row],[IVA]]-Imput[[#This Row],[Retención / IEPS / Descuento]] -> 626.9968 | M21: 626.9968 | N21: Factura | P21: C9962DA0-0F24-4E39-AB09-A4E4E83DB95D | Q21: A521 | R21: 45832 | S21: 04.- TDC | V21: VIATICOS | W21: ALIMENTOS
B22: JUN 2025 Q2 | C22: C2-8 | D22: CFC110121742 | E22: =IFERROR(IF(_xlfn.XLOOKUP(Imput[[#This Row],[RFC]],'Alta Proveedor'!D:D,'Alta Proveedor'!E:E)=0,"",_xlfn.XLOOKUP(Imput[[#This Row],[RFC]],'Alta Proveedor'!D:D,'Alta Proveedor'!E:E)),"") -> COMERCIALIZADORA FARMACEUTICA DE CHIAPAS | F22: PEAJES - TAG PASE PORTATIL BLIST 8851 | G22: 1 | H22: 129.31 | I22: =Imput[[#This Row],[Cantidad]]*Imput[[#This Row],[Precio Unitario]] -> 129.31 | J22: =Imput[[#This Row],[Sub total]]*0.16 -> 20.6896 | K22: 0 | L22: =Imput[[#This Row],[Sub total]]+Imput[[#This Row],[IVA]]-Imput[[#This Row],[Retención / IEPS / Descuento]] -> 149.9996 | M22: 149.9996 | N22: Factura | P22: 9F6AA786-45F6-4405-9F1C-E3EF43A818C0 | Q22: 9F6AA786 | R22: 45832 | S22: 04.- TDC | V22: VIATICOS | W22: PEAJES
B23: JUN 2025 Q2 | C23: C2-2 | D23: RUVL810825597 | E23: =IFERROR(IF(_xlfn.XLOOKUP(Imput[[#This Row],[RFC]],'Alta Proveedor'!D:D,'Alta Proveedor'!E:E)=0,"",_xlfn.XLOOKUP(Imput[[#This Row],[RFC]],'Alta Proveedor'!D:D,'Alta Proveedor'!E:E)),"") -> LUISA MARIA RUIZ VARGAS "MATRIX PASION POR TU AUTO" | F23: SERVICIO DE ALINEACION DELANTERA | G23: 1 | H23: 172.4149 | I23: =Imput[[#This Row],[Cantidad]]*Imput[[#This Row],[Precio Unitario]] -> 172.4149 | J23: =Imput[[#This Row],[Sub total]]*0.16 -> 27.586384 | K23: 0 | L23: =Imput[[#This Row],[Sub total]]+Imput[[#This Row],[IVA]]-Imput[[#This Row],[Retención / IEPS / Descuento]] -> 200.00128 | M23: 12000.002 | N23: Factura | P23: CA1ACE20-1B70-507A-8A63-A4D529FBC89C | Q23: FACTTAP2AARIA-1 | R23: 45832 | S23: 28.- TDD | V23: EQUIPO | W23: LLANTAS
B24: JUN 2025 Q2 | C24: C2-2 | D24: RUVL810825597 | E24: =IFERROR(IF(_xlfn.XLOOKUP(Imput[[#This Row],[RFC]],'Alta Proveedor'!D:D,'Alta Proveedor'!E:E)=0,"",_xlfn.XLOOKUP(Imput[[#This Row],[RFC]],'Alta Proveedor'!D:D,'Alta Proveedor'!E:E)),"") -> LUISA MARIA RUIZ VARGAS "MATRIX PASION POR TU AUTO" | F24: NEUMATICOS - 425/75/16 |LINK PENTERRA R/T AUTO 111Q | G24: 4 | H24: =10172.414/4 -> 2543.1035 | I24: =Imput[[#This Row],[Cantidad]]*Imput[[#This Row],[Precio Unitario]] -> 10172.414 | J24: =Imput[[#This Row],[Sub total]]*0.16 -> 1627.5862 | K24: 0 | L24: =Imput[[#This Row],[Sub total]]+Imput[[#This Row],[IVA]]-Imput[[#This Row],[Retención / IEPS / Descuento]] -> 11800 | M24: 0 | N24: Factura | P24: CA1ACE20-1B70-507A-8A63-A4D529FBC89C | Q24: FACTTAP2AARIA-1 | R24: 45832 | S24: 28.- TDD | V24: EQUIPO | W24: LLANTAS
B25: JUN 2025 Q2 | C25: C2-2 | D25: ROGM701116LV6 | E25: =IFERROR(IF(_xlfn.XLOOKUP(Imput[[#This Row],[RFC]],'Alta Proveedor'!D:D,'Alta Proveedor'!E:E)=0,"",_xlfn.XLOOKUP(Imput[[#This Row],[RFC]],'Alta Proveedor'!D:D,'Alta Proveedor'!E:E)),"") -> MIGUEL ANGEL ROCHA GARCIA | F25: VENTA E INSTALACION DE AUTOESTEREO | G25: 1 | H25: 2000 | I25: =Imput[[#This Row],[Cantidad]]*Imput[[#This Row],[Precio Unitario]] -> 2000 | J25: =Imput[[#This Row],[Sub total]]*0.16 -> 320 | K25: 25 | L25: =Imput[[#This Row],[Sub total]]+Imput[[#This Row],[IVA]]-Imput[[#This Row],[Retención / IEPS / Descuento]] -> 2295 | M25: 2295 | N25: Factura | P25: 8938DE0F-DB7C-43AF-AF01-2203691A7DE2 | Q25: 25 | R25: 45833 | S25: 03.- Transferencia | V25: EQUIPO | W25: ESTEREO
B26: JUN 2025 Q2 | C26: C4-6 | D26: LOZ170722KGA | E26: =IFERROR(IF(_xlfn.XLOOKUP(Imput[[#This Row],[RFC]],'Alta Proveedor'!D:D,'Alta Proveedor'!E:E)=0,"",_xlfn.XLOOKUP(Imput[[#This Row],[RFC]],'Alta Proveedor'!D:D,'Alta Proveedor'!E:E)),"") -> EL LINDERO DE OZULUAMA (RESTAURANTE) | F26: RESTAURANTE - CONSUMO DE ALIMENTOS Y BEBIDAS | G26: 1 | H26: 780.17 | I26: =Imput[[#This Row],[Cantidad]]*Imput[[#This Row],[Precio Unitario]] -> 780.17 | J26: =Imput[[#This Row],[Sub total]]*0.16 -> 124.8272 | K26: -91 | L26: =Imput[[#This Row],[Sub total]]+Imput[[#This Row],[IVA]]-Imput[[#This Row],[Retención / IEPS / Descuento]] -> 995.9972 | M26: 995.9972 | N26: Factura | P26: 34B4401D-17B3-4812-B93C-A9F3F78362E4 | Q26: A25504 | R26: 45834 | S26: 04.- TDC | V26: VIATICOS | W26: ALIMENTOS
B27: JUN 2025 Q2 | C27: C2-7 | D27: ROBL4512274I1 | E27: =IFERROR(IF(_xlfn.XLOOKUP(Imput[[#This Row],[RFC]],'Alta Proveedor'!D:D,'Alta Proveedor'!E:E)=0,"",_xlfn.XLOOKUP(Imput[[#This Row],[RFC]],'Alta Proveedor'!D:D,'Alta Proveedor'!E:E)),"") -> Estacion de servicio No. 6580 JOSE LUIS RODRIGUEZ BERLANGA (COMBUSTIBLES) | F27: COMBUSTIBLE - SUPERIOR (2568444) | G27: 40 | H27: 21.05725 | I27: =Imput[[#This Row],[Cantidad]]*Imput[[#This Row],[Precio Unitario]] -> 842.29 | J27: 130.51 | K27: 0 | L27: =Imput[[#This Row],[Sub total]]+Imput[[#This Row],[IVA]]-Imput[[#This Row],[Retención / IEPS / Descuento]] -> 972.8 | M27: 972.8 | N27: Factura | P27: 1D2F8ECD-2A80-4538-A399-1624FA1F055D | Q27: AL 41,793 | R27: 45834 | S27: 04.- TDC | V27: COMBUSTIBLES | W27: GASOLINA
B28: JUN 2025 Q2 | C28: C4-6 | D28: MASR990207BB1 | E28: =IFERROR(IF(_xlfn.XLOOKUP(Imput[[#This Row],[RFC]],'Alta Proveedor'!D:D,'Alta Proveedor'!E:E)=0,"",_xlfn.XLOOKUP(Imput[[#This Row],[RFC]],'Alta Proveedor'!D:D,'Alta Proveedor'!E:E)),"") -> RICARDO MARTINEZ SALAZAR (RESTAURANTE) | F28: RESTAURANTE - CONSUMO DE ALIMENTOS | G28: 1 | H28: 222.21 | I28: =Imput[[#This Row],[Cantidad]]*Imput[[#This Row],[Precio Unitario]] -> 222.21 | J28: =Imput[[#This Row],[Sub total]]*0.16 -> 35.5536 | K28: 2.76 | L28: =Imput[[#This Row],[Sub total]]+Imput[[#This Row],[IVA]]-Imput[[#This Row],[Retención / IEPS / Descuento]] -> 255.0036 | M28: 255.0036 | N28: Factura | P28: FC034230-6E26-4268-A931-30F92C1A5B2E | Q28: FC034230 | R28: 45834 | S28: 04.- TDC | V28: VIATICOS | W28: ALIMENTOS
B29: JUN 2025 Q2 | C29: C4-6 | D29: GUCA670908V23 | E29: =IFERROR(IF(_xlfn.XLOOKUP(Imput[[#This Row],[RFC]],'Alta Proveedor'!D:D,'Alta Proveedor'!E:E)=0,"",_xlfn.XLOOKUP(Imput[[#This Row],[RFC]],'Alta Proveedor'!D:D,'Alta Proveedor'!E:E)),"") -> AUGUSTO EDUARDO GUERRERO CRUZ (RESTAURANTE) | F29: RESTAURANTE - CONSUMO DE ALIMENTOS Y BEBIDAS | G29: 1 | H29: 275.86 | I29: =Imput[[#This Row],[Cantidad]]*Imput[[#This Row],[Precio Unitario]] -> 275.86 | J29: =Imput[[#This Row],[Sub total]]*0.16 -> 44.1376 | K29: 0 | L29: =Imput[[#This Row],[Sub total]]+Imput[[#This Row],[IVA]]-Imput[[#This Row],[Retención / IEPS / Descuento]] -> 319.9976 | M29: 319.9976 | N29: Factura | P29: ADC076A2-81A0-4ED6-8F21-2674B7727006 | Q29: C36051 | R29: 45835 | S29: 28.- TDD | V29: VIATICOS | W29: ALIMENTOS
B30: JUN 2025 Q2 | C30: C4-6 | D30: MAS0810247C0 | E30: =IFERROR(IF(_xlfn.XLOOKUP(Imput[[#This Row],[RFC]],'Alta Proveedor'!D:D,'Alta Proveedor'!E:E)=0,"",_xlfn.XLOOKUP(Imput[[#This Row],[RFC]],'Alta Proveedor'!D:D,'Alta Proveedor'!E:E)),"") -> POPAT BAZAR SA DE CV "BUFFALITAS, BUFFALO WINGS, BURGUERS Y RIBS" (RESTAURANTE) | F30: RESTAURANTE - CONSUMO DE ALIMENTOS | G30: 1 | H30: 468.1 | I30: =Imput[[#This Row],[Cantidad]]*Imput[[#This Row],[Precio Unitario]] -> 468.1 | J30: =Imput[[#This Row],[Sub total]]*0.16 -> 74.896 | K30: 0 | L30: =Imput[[#This Row],[Sub total]]+Imput[[#This Row],[IVA]]-Imput[[#This Row],[Retención / IEPS / Descuento]] -> 542.996 | M30: 542.996 | N30: Factura | P30: 09CC0777-4F02-4EDB-92C4-C5C3B4C68612 | Q30: B 12748 | R30: 45835 | V30: VIATICOS | W30: ALIMENTOS
B31: JUN 2025 Q2 | C31: TAM-P1-5 | D31: Nomina-OPERACIÓN | E31: =IFERROR(IF(_xlfn.XLOOKUP(Imput[[#This Row],[RFC]],'Alta Proveedor'!D:D,'Alta Proveedor'!E:E)=0,"",_xlfn.XLOOKUP(Imput[[#This Row],[RFC]],'Alta Proveedor'!D:D,'Alta Proveedor'!E:E)),"") -> Nomina-OPERACIÓN | F31: MARIA ISABEL DE ANGEL | ANTICIPO EXCAVACION | G31: 1 | H31: 40000 | I31: =Imput[[#This Row],[Cantidad]]*Imput[[#This Row],[Precio Unitario]] -> 40000 | J31: =Imput[[#This Row],[Sub total]]*0.08 -> 3200 | K31: 0 | L31: =Imput[[#This Row],[Sub total]]+Imput[[#This Row],[IVA]]-Imput[[#This Row],[Retención / IEPS / Descuento]] -> 43200 | M31: 43200 | R31: 45835 | S31: 03.- Transferencia | U31: GASTOS SIN FACTURA | V31: NOMINA | W31: EXCAVACIÓN
B32: JUN 2025 Q2 | C32: TAM-P4-10 | D32: HDM001017AS1 THD-8730 TAMPICO | E32: =IFERROR(IF(_xlfn.XLOOKUP(Imput[[#This Row],[RFC]],'Alta Proveedor'!D:D,'Alta Proveedor'!E:E)=0,"",_xlfn.XLOOKUP(Imput[[#This Row],[RFC]],'Alta Proveedor'!D:D,'Alta Proveedor'!E:E)),"") -> HOME DEPOT MEXICO SUCURSAL THD-8730 TAMPICO | F32: SEGURIDAD - MALLA DE CONSTRUCCION PERIMETRAL 30 | G32: 1 | H32: 244.14 | I32: =Imput[[#This Row],[Cantidad]]*Imput[[#This Row],[Precio Unitario]] -> 244.14 | J32: =Imput[[#This Row],[Sub total]]*0.16 -> 39.0624 | K32: 0 | L32: =Imput[[#This Row],[Sub total]]+Imput[[#This Row],[IVA]]-Imput[[#This Row],[Retención / IEPS / Descuento]] -> 283.2024 | M32: 283.2024 | N32: Factura | P32: 507470aa-9f63-4a0a-a207-ca155033901a | Q32: 4HGCJI 424199 | R32: 45836 | S32: 04.- TDC | V32: MATERIAL | W32: MATERIAL CONSTRUCCIÓN
B33: JUN 2025 Q2 | C33: C2-7 | D33: CLG130128KA0 | E33: =IFERROR(IF(_xlfn.XLOOKUP(Imput[[#This Row],[RFC]],'Alta Proveedor'!D:D,'Alta Proveedor'!E:E)=0,"",_xlfn.XLOOKUP(Imput[[#This Row],[RFC]],'Alta Proveedor'!D:D,'Alta Proveedor'!E:E)),"") -> E12196 COMBUSTIBLES Y LUBRICANTES GHN (COMBUSTIBLES) | F33: COMBUSTIBLE - PREMIUM (nota 2493616-0) | G33: 30.897 | H33: 22.423483 | I33: =Imput[[#This Row],[Cantidad]]*Imput[[#This Row],[Precio Unitario]] -> 692.81835 | J33: 107.41 | K33: 0 | L33: =Imput[[#This Row],[Sub total]]+Imput[[#This Row],[IVA]]-Imput[[#This Row],[Retención / IEPS / Descuento]] -> 800.22835 | M33: 800.22835 | N33: Factura | P33: 9291d69b-13bb-4ebc-8011-3a781f4f9635 | Q33: LW 20834 | R33: 45836 | S33: 04.- TDC | V33: COMBURSTIBLES | W33: GASOLINA
B34: JUN 2025 Q2 | C34: TAM-P4-17 | D34: MAS991101DH9 | E34: =IFERROR(IF(_xlfn.XLOOKUP(Imput[[#This Row],[RFC]],'Alta Proveedor'!D:D,'Alta Proveedor'!E:E)=0,"",_xlfn.XLOOKUP(Imput[[#This Row],[RFC]],'Alta Proveedor'!D:D,'Alta Proveedor'!E:E)),"") -> MASYFERR (FERRETERIA) | F34: MATERIAL - VARILLA CORRUGADA CON NORMA, AR-42 19MM=3/4"X12M | G34: 65 | H34: 443.9655 | I34: =Imput[[#This Row],[Cantidad]]*Imput[[#This Row],[Precio Unitario]] -> 28857.757 | J34: =Imput[[#This Row],[Sub total]]*0.16 -> 4617.2412 | K34: 0 | L34: =Imput[[#This Row],[Sub total]]+Imput[[#This Row],[IVA]]-Imput[[#This Row],[Retención / IEPS / Descuento]] -> 33474.999 | M34: 40280.395 | N34: Factura | P34: 28E77138-2279-47FA-AA83-52165F350500 | Q34: M-0451984 | R34: 45836 | S34: 04.- TDC | V34: MATERIAL | W34: MATERIAL CONSTRUCCIÓN
B35: JUN 2025 Q2 | C35: TAM-P4-4 | D35: MAS991101DH9 | E35: =IFERROR(IF(_xlfn.XLOOKUP(Imput[[#This Row],[RFC]],'Alta Proveedor'!D:D,'Alta Proveedor'!E:E)=0,"",_xlfn.XLOOKUP(Imput[[#This Row],[RFC]],'Alta Proveedor'!D:D,'Alta Proveedor'!E:E)),"") -> MASYFERR (FERRETERIA) | F35: MATERIAL - ALAMBRE QUEMADO BOBINA | G35: 50 | H35: 20.2586 | I35: =Imput[[#This Row],[Cantidad]]*Imput[[#This Row],[Precio Unitario]] -> 1012.93 | J35: =Imput[[#This Row],[Sub total]]*0.16 -> 162.0688 | K35: 0 | L35: =Imput[[#This Row],[Sub total]]+Imput[[#This Row],[IVA]]-Imput[[#This Row],[Retención / IEPS / Descuento]] -> 1174.9988 | M35: 0 | N35: Factura | P35: 28E77138-2279-47FA-AA83-52165F350500 | Q35: M-0451984 | R35: 45836 | S35: 04.- TDC | V35: MATERIAL | W35: MATERIAL CONSTRUCCIÓN
B36: JUN 2025 Q2 | C36: TAM-P4-16 | D36: MAS991101DH9 | E36: =IFERROR(IF(_xlfn.XLOOKUP(Imput[[#This Row],[RFC]],'Alta Proveedor'!D:D,'Alta Proveedor'!E:E)=0,"",_xlfn.XLOOKUP(Imput[[#This Row],[RFC]],'Alta Proveedor'!D:D,'Alta Proveedor'!E:E)),"") -> MASYFERR (FERRETERIA) | F36: MATERIAL - VARILLA CORRUGADA CON NORMA, AR-42 10MM=3/8"X12M | G36: 46 | H36: 105.5172 | I36: =Imput[[#This Row],[Cantidad]]*Imput[[#This Row],[Precio Unitario]] -> 4853.7912 | J36: =Imput[[#This Row],[Sub total]]*0.16 -> 776.60659 | K36: 0 | L36: =Imput[[#This Row],[Sub total]]+Imput[[#This Row],[IVA]]-Imput[[#This Row],[Retención / IEPS / Descuento]] -> 5630.3978 | M36: 0 | N36: Factura | P36: 28E77138-2279-47FA-AA83-52165F350500 | Q36: M-0451984 | R36: 45836 | S36: 04.- TDC | V36: MATERIAL | W36: MATERIAL CONSTRUCCIÓN
B37: JUN 2025 Q2 | C37: TAM-P4-17 | D37: MAS991101DH9 | E37: =IFERROR(IF(_xlfn.XLOOKUP(Imput[[#This Row],[RFC]],'Alta Proveedor'!D:D,'Alta Proveedor'!E:E)=0,"",_xlfn.XLOOKUP(Imput[[#This Row],[RFC]],'Alta Proveedor'!D:D,'Alta Proveedor'!E:E)),"") -> MASYFERR (FERRETERIA) | F37: MATERIAL - BONIFICACION EN PRECIO | G37: =-1/3 -> -0.33333333 | H37: 253.79 | I37: =Imput[[#This Row],[Cantidad]]*Imput[[#This Row],[Precio Unitario]] -> -84.596667 | J37: =Imput[[#This Row],[Sub total]]*0.16 -> -13.535467 | K37: 0 | L37: =Imput[[#This Row],[Sub total]]+Imput[[#This Row],[IVA]]-Imput[[#This Row],[Retención / IEPS / Descuento]] -> -98.132133 | M37: -294.3964 | N37: Nota de Crédito | P37: CC11F747-27C0-4143-A3B5-9B5C96219A58 | Q37: ME-0022968 | R37: 45836 | S37: 04.- TDC | V37: MATERIAL | W37: MATERIAL CONSTRUCCIÓN
B38: JUN 2025 Q2 | C38: TAM-P4-4 | D38: MAS991101DH9 | E38: =IFERROR(IF(_xlfn.XLOOKUP(Imput[[#This Row],[RFC]],'Alta Proveedor'!D:D,'Alta Proveedor'!E:E)=0,"",_xlfn.XLOOKUP(Imput[[#This Row],[RFC]],'Alta Proveedor'!D:D,'Alta Proveedor'!E:E)),"") -> MASYFERR (FERRETERIA) | F38: MATERIAL - BONIFICACION EN PRECIO | G38: =-1/3 -> -0.33333333 | H38: 253.79 | I38: =Imput[[#This Row],[Cantidad]]*Imput[[#This Row],[Precio Unitario]] -> -84.596667 | J38: =Imput[[#This Row],[Sub total]]*0.16 -> -13.535467 | K38: 0 | L38: =Imput[[#This Row],[Sub total]]+Imput[[#This Row],[IVA]]-Imput[[#This Row],[Retención / IEPS / Descuento]] -> -98.132133 | M38: 0 | N38: Nota de Crédito | P38: CC11F747-27C0-4143-A3B5-9B5C96219A58 | Q38: ME-0022968 | R38: 45836 | S38: 04.- TDC | V38: MATERIAL | W38: MATERIAL CONSTRUCCIÓN
B39: JUN 2025 Q2 | C39: TAM-P4-16 | D39: MAS991101DH9 | E39: =IFERROR(IF(_xlfn.XLOOKUP(Imput[[#This Row],[RFC]],'Alta Proveedor'!D:D,'Alta Proveedor'!E:E)=0,"",_xlfn.XLOOKUP(Imput[[#This Row],[RFC]],'Alta Proveedor'!D:D,'Alta Proveedor'!E:E)),"") -> MASYFERR (FERRETERIA) | F39: MATERIAL - BONIFICACION EN PRECIO | G39: =-1/3 -> -0.33333333 | H39: 253.79 | I39: =Imput[[#This Row],[Cantidad]]*Imput[[#This Row],[Precio Unitario]] -> -84.596667 | J39: =Imput[[#This Row],[Sub total]]*0.16 -> -13.535467 | K39: 0 | L39: =Imput[[#This Row],[Sub total]]+Imput[[#This Row],[IVA]]-Imput[[#This Row],[Retención / IEPS / Descuento]] -> -98.132133 | M39: 0 | N39: Nota de Crédito | P39: CC11F747-27C0-4143-A3B5-9B5C96219A58 | Q39: ME-0022968 | R39: 45836 | S39: 04.- TDC | V39: MATERIAL | W39: MATERIAL CONSTRUCCIÓN
B40: JUN 2025 Q2 | C40: C4-6 | D40: GUCA670908V23 | E40: =IFERROR(IF(_xlfn.XLOOKUP(Imput[[#This Row],[RFC]],'Alta Proveedor'!D:D,'Alta Proveedor'!E:E)=0,"",_xlfn.XLOOKUP(Imput[[#This Row],[RFC]],'Alta Proveedor'!D:D,'Alta Proveedor'!E:E)),"") -> AUGUSTO EDUARDO GUERRERO CRUZ (RESTAURANTE) | F40: RESTAURANTE - CONSUMO DE ALIMENTOS Y BEBIDAS | G40: 1 | H40: 185.344 | I40: =Imput[[#This Row],[Cantidad]]*Imput[[#This Row],[Precio Unitario]] -> 185.344 | J40: =Imput[[#This Row],[Sub total]]*0.16 -> 29.65504 | K40: 0 | L40: =Imput[[#This Row],[Sub total]]+Imput[[#This Row],[IVA]]-Imput[[#This Row],[Retención / IEPS / Descuento]] -> 214.99904 | M40: 214.99904 | N40: Factura | P40: 179D7540-D9E6-479B-BC61-1FFC4D745199 | Q40: C36106 | R40: 45837 | S40: 04.- TDC | V40: VIATICOS | W40: ALIMENTOS
B41: JUN 2025 Q2 | C41: TAM-P1-5 | D41: Nomina-OPERACIÓN | E41: =IFERROR(IF(_xlfn.XLOOKUP(Imput[[#This Row],[RFC]],'Alta Proveedor'!D:D,'Alta Proveedor'!E:E)=0,"",_xlfn.XLOOKUP(Imput[[#This Row],[RFC]],'Alta Proveedor'!D:D,'Alta Proveedor'!E:E)),"") -> Nomina-OPERACIÓN | F41: EDGAR FRANCISCO FRANCO | PAGO 10% | G41: 1 | H41: 15000 | I41: =Imput[[#This Row],[Cantidad]]*Imput[[#This Row],[Precio Unitario]] -> 15000 | J41: =Imput[[#This Row],[Sub total]]*0.08 -> 1200 | K41: 0 | L41: =Imput[[#This Row],[Sub total]]+Imput[[#This Row],[IVA]]-Imput[[#This Row],[Retención / IEPS / Descuento]] -> 16200 | M41: 16200 | R41: 45837 | S41: 03.- Transferencia | U41: GASTOS SIN FACTURA | V41: NOMINA | W41: EXCAVACIÓN
B42: JUN 2025 Q2 | C42: C4-6 | D42: DLI931201MI9 | E42: =IFERROR(IF(_xlfn.XLOOKUP(Imput[[#This Row],[RFC]],'Alta Proveedor'!D:D,'Alta Proveedor'!E:E)=0,"",_xlfn.XLOOKUP(Imput[[#This Row],[RFC]],'Alta Proveedor'!D:D,'Alta Proveedor'!E:E)),"") -> DISTRIBUIDORA LIVERPOOL | F42: RESTAURANTE - CONSUMO RESTAURANTE | G42: 1 | H42: 275 | I42: =Imput[[#This Row],[Cantidad]]*Imput[[#This Row],[Precio Unitario]] -> 275 | J42: =Imput[[#This Row],[Sub total]]*0.16 -> 44 | K42: 0 | L42: =Imput[[#This Row],[Sub total]]+Imput[[#This Row],[IVA]]-Imput[[#This Row],[Retención / IEPS / Descuento]] -> 319 | M42: 319 | N42: Factura | P42: AC3CF806-DF84-5ED4-9EC5-3D0A6934EF17 | Q42: LWIU 455938 | R42: 45838 | S42: 04.- TDC | V42: VIATICOS | W42: ALIMENTOS
B43: JUN 2025 Q2 | C43: TAM-P4-9 | D43: UAGG890111FP7 | E43: =IFERROR(IF(_xlfn.XLOOKUP(Imput[[#This Row],[RFC]],'Alta Proveedor'!D:D,'Alta Proveedor'!E:E)=0,"",_xlfn.XLOOKUP(Imput[[#This Row],[RFC]],'Alta Proveedor'!D:D,'Alta Proveedor'!E:E)),"") -> GUILLERMO UMAÑA GONZALEZ | F43: MATERIAL - 11121616 ‐ Madera de pino MADERA 2X4X10 | G43: 4 | H43: 129.31 | I43: =Imput[[#This Row],[Cantidad]]*Imput[[#This Row],[Precio Unitario]] -> 517.24 | J43: =Imput[[#This Row],[Sub total]]*0.16 -> 82.7584 | K43: 0 | L43: =Imput[[#This Row],[Sub total]]+Imput[[#This Row],[IVA]]-Imput[[#This Row],[Retención / IEPS / Descuento]] -> 599.9984 | M43: 1680.0048 | N43: Factura | P43: E5677537‐B090‐46EB‐BDFA‐92F852D2C812 | Q43: F ‐ 5664 | R43: 45838 | S43: 04.- TDC | V43: MATERIAL | W43: MATERIAL CONSTRUCCIÓN
B44: JUN 2025 Q2 | C44: TAM-P4-9 | D44: UAGG890111FP7 | E44: =IFERROR(IF(_xlfn.XLOOKUP(Imput[[#This Row],[RFC]],'Alta Proveedor'!D:D,'Alta Proveedor'!E:E)=0,"",_xlfn.XLOOKUP(Imput[[#This Row],[RFC]],'Alta Proveedor'!D:D,'Alta Proveedor'!E:E)),"") -> GUILLERMO UMAÑA GONZALEZ | F44: MATERIAL - 11121616 ‐ Madera de pino 2X8X8 | G44: 2 | H44: 224.14 | I44: =Imput[[#This Row],[Cantidad]]*Imput[[#This Row],[Precio Unitario]] -> 448.28 | J44: =Imput[[#This Row],[Sub total]]*0.16 -> 71.7248 | K44: 0 | L44: =Imput[[#This Row],[Sub total]]+Imput[[#This Row],[IVA]]-Imput[[#This Row],[Retención / IEPS / Descuento]] -> 520.0048 | M44: 0 | N44: Factura | P44: E5677537‐B090‐46EB‐BDFA‐92F852D2C812 | Q44: F ‐ 5664 | R44: 45838 | S44: 04.- TDC | V44: MATERIAL | W44: MATERIAL CONSTRUCCIÓN
...

Sheet Alta Proveedor
B2: No. | D2: Datos de Empresa
D3: RFC | E3: RAZON SOCIAL
B4: 1 | D4: MAS991101DH9 | E4: MASYFERR (FERRETERIA)
B5: =B4+1 -> 2 | D5: ANA050518RL1 | E5: AEROENLACES NACIONALES (VUELOS)
B6: =B5+1 -> 3 | D6: CFC110121742 | E6: COMERCIALIZADORA FARMACEUTICA DE CHIAPAS
B7: =B6+1 -> 4 | D7: CLG130128KA0 | E7: E12196 COMBUSTIBLES Y LUBRICANTES GHN (COMBUSTIBLES)
B8: =B7+1 -> 5 | D8: DLI931201MI9 | E8: DISTRIBUIDORA LIVERPOOL
B9: =B8+1 -> 6 | D9: FCU220209NQ1 | E9: FERRETERIA CUERVO SA DE CV
B10: =B9+1 -> 7 | D10: CAHE700209ATA | E10: ELVIA CABRERA HUERTA "MI PUEBLITO, MMM… QUE SABOR" (RESTAURANTE)
B11: =B10+1 -> 8 | D11: GUCA670908V23 | E11: AUGUSTO EDUARDO GUERRERO CRUZ (RESTAURANTE)
B12: =B11+1 -> 9 | D12: HDM001017AS1 THD-8730 TAMPICO | E12: HOME DEPOT MEXICO SUCURSAL THD-8730 TAMPICO
B13: =B12+1 -> 10 | D13: LOZ170722KGA | E13: EL LINDERO DE OZULUAMA (RESTAURANTE)
B14: =B13+1 -> 11 | D14: MASR990207BB1 | E14: RICARDO MARTINEZ SALAZAR (RESTAURANTE)
B15: =B14+1 -> 12 | D15: MAS0810247C0 | E15: POPAT BAZAR SA DE CV "BUFFALITAS, BUFFALO WINGS, BURGUERS Y RIBS" (RESTAURANTE)
B16: =B15+1 -> 13 | D16: PFL981207AX5 | E16: PERFILES DE FIERRO Y LAMINA ATIYE "ACEROTAM"
... B230: =B229+1 -> 227 | D230: AUSV591108T12 | E230: TORNILLOS SAN CRISTOBAL (VICTORINO DELFINO AGUILAR SANCHEZ)
B231: =B230+1 -> 228
B232: =B231+1 -> 229
B233: =B232+1 -> 230
B234: =B233+1 -> 231
B235: =B234+1 -> 232
B236: =B235+1 -> 233
B237: =B236+1 -> 234
B238: =B237+1 -> 235
B239: =B238+1 -> 236
B240: =B239+1 -> 237
B241: =B240+1 -> 238
B242: =B241+1 -> 239
... B303: =B302+1 -> 300

Sheet Hoja Auxiliar
C2: PERIODO Imp. | D2: COMPRENDE | G2: C. Imp. | H2: Familia | J2: Tipo de Pago | L2: Estatus de Pago | N2: Tipo | P2: APLICA
D3: DESDE | E3: HASTA
G4: C. Imp. | H4: Familia
B5: 1 | C5: JUN 2025 Q1 | D5: 45809 | E5: =D6-1 -> 45823 | G5: ='Indirect Costs'!C11 -> C1 | H5: =_xlfn.XLOOKUP(G5,'Indirect Costs'!C:C,'Indirect Costs'!D:D) -> PERSONAL | J5: 01.- Efectivo | L5: Atrasado | N5: Cancelación | P5: AMORT. ANTICIPO
B6: 2 | C6: JUN 2025 Q2 | D6: 45824 | E6: =D7-1 -> 45838 | G6: ='Indirect Costs'!C13 -> C1-1 | H6: =_xlfn.XLOOKUP(G6,'Indirect Costs'!C:C,'Indirect Costs'!D:D) -> Gerente de Proyecto | J6: 03.- Transferencia | L6: Pagado | N6: Comprobante de pago | P6: ANTICIPO
B7: 3 | C7: JUL 2025 Q1 | D7: 45839 | E7: =D8-1 -> 45853 | G7: ='Indirect Costs'!C14 -> C1-2 | H7: =_xlfn.XLOOKUP(G7,'Indirect Costs'!C:C,'Indirect Costs'!D:D) -> Gerente Estratégico | J7: 04.- TDC | L7: Pendiente | N7: Factura | P7: DEDUCTIVA
B8: 4 | C8: JUL 2025 Q2 | D8: 45854 | E8: =D9-1 -> 45869 | G8: ='Indirect Costs'!C15 -> C1-3 | H8: =_xlfn.XLOOKUP(G8,'Indirect Costs'!C:C,'Indirect Costs'!D:D) -> Gerente Administración | J8: 06.- Dinero Electrónico | L8: Sobrepagado | N8: Nota de Crédito | P8: ESTIMACION
B9: 5 | C9: AGO 2025 Q1 | D9: 45870 | E9: =D10-1 -> 45884 | G9: ='Indirect Costs'!C16 -> C1-4 | H9: =_xlfn.XLOOKUP(G9,'Indirect Costs'!C:C,'Indirect Costs'!D:D) -> Técnico de compras/ control de Costos | J9: 15.- Condonación | N9: Provisión | P9: RETENCION 5%
B10: 6 | C10: AGO 2025 Q2 | D10: 45885 | E10: =D11-1 -> 45900 | G10: ='Indirect Costs'!C17 -> C1-5 | H10: =_xlfn.XLOOKUP(G10,'Indirect Costs'!C:C,'Indirect Costs'!D:D) -> Aux. Administrativo | J10: 27.- A Satisfaccion del Acreedor | N10: Recibo
B11: 7 | C11: SEP 2025 Q1 | D11: 45901 | E11: =D12-1 -> 45915 | G11: ='Indirect Costs'!C19 -> C1-6 | H11: =_xlfn.XLOOKUP(G11,'Indirect Costs'!C:C,'Indirect Costs'!D:D) -> Superintendente | J11: 28.- TDD | N11: Prefactura
B12: 8 | C12: SEP 2025 Q2 | D12: 45916 | E12: =D13-1 -> 45930 | G12: ='Indirect Costs'!C20 -> C1-7 | H12: =_xlfn.XLOOKUP(G12,'Indirect Costs'!C:C,'Indirect Costs'!D:D) -> Jefe de Producción | J12: 30.- Aplicación de Anticipos | N12: Comprobante de Ingresos
B13: 9 | C13: OCT 2025 Q1 | D13: 45931 | E13: =D14-1 -> 45945 | G13: ='Indirect Costs'!C21 -> C1-8 | H13: =_xlfn.XLOOKUP(G13,'Indirect Costs'!C:C,'Indirect Costs'!D:D) -> Supervisor 1 | J13: 31.- Intermediario Pagos | N13: CAJA CHICA
B14: 10 | C14: OCT 2025 Q2 | D14: 45946 | E14: =D15-1 -> 45961 | G14: ='Indirect Costs'!C22 -> C1-9 | H14: =_xlfn.XLOOKUP(G14,'Indirect Costs'!C:C,'Indirect Costs'!D:D) -> Supervisor 2 | J14: 99.- Por Definir
B15: 11 | C15: NOV 2025 Q1 | D15: 45962 | E15: =D16-1 -> 45976 | G15: ='Indirect Costs'!C23 -> C1-10 | H15: =_xlfn.XLOOKUP(G15,'Indirect Costs'!C:C,'Indirect Costs'!D:D) -> Supervisor 3 | J15: PPD.- Pago en parcialidades o diferido
B16: 12 | C16: NOV 2025 Q2 | D16: 45977 | E16: =D17-1 -> 45991 | G16: ='Indirect Costs'!C25 -> C1-11 | H16: =_xlfn.XLOOKUP(G16,'Indirect Costs'!C:C,'Indirect Costs'!D:D) -> Ingeniero de Diseño (Responsable del Proyecto)
B17: 13 | C17: DIC 2025 Q1 | D17: 45992 | E17: =D18-1 -> 46006 | G17: ='Indirect Costs'!C26 -> C1-12 | H17: =_xlfn.XLOOKUP(G17,'Indirect Costs'!C:C,'Indirect Costs'!D:D) -> Coordinador BIM
B18: 14 | C18: DIC 2025 Q2 | D18: 46007 | E18: =D19-1 -> 46022 | G18: ='Indirect Costs'!C27 -> C1-13 | H18: =_xlfn.XLOOKUP(G18,'Indirect Costs'!C:C,'Indirect Costs'!D:D) -> Especialista de Disciplina BIM
B19: 15 | C19: ENE 2026 Q1 | D19: 46023 | E19: =D20-1 -> 46037 | G19: ='Indirect Costs'!C28 -> C1-14 | H19: =_xlfn.XLOOKUP(G19,'Indirect Costs'!C:C,'Indirect Costs'!D:D) -> Gestor de Información BIM
B20: 16 | C20: ENE 2026 Q2 | D20: 46038 | E20: =D21-1 -> 46053 | G20: ='Indirect Costs'!C29 -> C1-15 | H20: =_xlfn.XLOOKUP(G20,'Indirect Costs'!C:C,'Indirect Costs'!D:D) -> Jefe de Topografía y Oficina Técnica
B21: 17 | C21: FEB 2026 Q1 | D21: 46054 | E21: =D22-1 -> 46068 | G21: ='Indirect Costs'!C30 -> C1-16 | H21: =_xlfn.XLOOKUP(G21,'Indirect Costs'!C:C,'Indirect Costs'!D:D) -> Topógrafo
B22: 18 | C22: FEB 2026 Q2 | D22: 46069 | E22: =D23-1 -> 46081 | G22: ='Indirect Costs'!C31 -> C1-17 | H22: =_xlfn.XLOOKUP(G22,'Indirect Costs'!C:C,'Indirect Costs'!D:D) -> Brigada Topografia (3 personas)
B23: 19 | C23: MAR 2026 Q1 | D23: 46082 | E23: =D24-1 -> 46096 | G23: ='Indirect Costs'!C32 -> C1-18 | H23: =_xlfn.XLOOKUP(G23,'Indirect Costs'!C:C,'Indirect Costs'!D:D) -> Jefe Estimaciones
B24: 20 | C24: MAR 2026 Q2 | D24: 46097 | E24: =D25-1 -> 46112 | G24: ='Indirect Costs'!C33 -> C1-19 | H24: =_xlfn.XLOOKUP(G24,'Indirect Costs'!C:C,'Indirect Costs'!D:D) -> Técnico Estimaciones
B25: 21 | C25: ABR 2026 Q1 | D25: 46113 | E25: =D26-1 -> 46127 | G25: ='Indirect Costs'!C35 -> C1-20 | H25: =_xlfn.XLOOKUP(G25,'Indirect Costs'!C:C,'Indirect Costs'!D:D) -> Jefe Seguridad e Higiene y Vialidad
B26: 22 | C26: ABR 2026 Q2 | D26: 46128 | E26: =D27-1 -> 46152 | G26: ='Indirect Costs'!C36 -> C1-21 | H26: =_xlfn.XLOOKUP(G26,'Indirect Costs'!C:C,'Indirect Costs'!D:D) -> Técnico Seguridad
B27: 23 | C27: MAY 2026 Q1 | D27: 46153 | E27: =D28-1 -> 46157 | G27: ='Indirect Costs'!C37 -> C1-22 | H27: =_xlfn.XLOOKUP(G27,'Indirect Costs'!C:C,'Indirect Costs'!D:D) -> Jefe Calidad y Medioambiente
B28: 24 | C28: MAY 2026 Q2 | D28: 46158 | E28: 46022 | G28: ='Indirect Costs'!C38 -> C1-23 | H28: =_xlfn.XLOOKUP(G28,'Indirect Costs'!C:C,'Indirect Costs'!D:D) -> Técnico Calidad y Medioambiente
B29: 25 | C29: JUN 2026 Q1 | D29: 46174 | E29: =D30-1 -> 46188 | G29: ='Indirect Costs'!C39 -> C1-24 | H29: =_xlfn.XLOOKUP(G29,'Indirect Costs'!C:C,'Indirect Costs'!D:D) -> Brigada Prevención (3 personas)
B30: 26 | C30: JUN 2026 Q2 | D30: 46189 | E30: =D31-1 -> 46203 | G30: ='Indirect Costs'!C41 -> C1-25 | H30: =_xlfn.XLOOKUP(G30,'Indirect Costs'!C:C,'Indirect Costs'!D:D) -> Jefe Planificación y Costes
B31: 27 | C31: JUL 2026 Q1 | D31: 46204 | E31: =D32-1 -> 46218 | G31: ='Indirect Costs'!C42 -> C1-26 | H31: =_xlfn.XLOOKUP(G31,'Indirect Costs'!C:C,'Indirect Costs'!D:D) -> Técnico Control Costes
B32: 28 | C32: JUL 2026 Q2 | D32: 46219 | E32: =D33-1 -> 46234 | G32: ='Indirect Costs'!C43 -> C1-27 | H32: =_xlfn.XLOOKUP(G32,'Indirect Costs'!C:C,'Indirect Costs'!D:D) -> Técnico Compras
B33: 29 | C33: AGO 2026 Q1 | D33: 46235 | E33: =D34-1 -> 46249 | G33: ='Indirect Costs'!C44 -> C1-28 | H33: =_xlfn.XLOOKUP(G33,'Indirect Costs'!C:C,'Indirect Costs'!D:D) -> Jefe Administración y Personal
B34: 30 | C34: AGO 2026 Q2 | D34: 46250 | E34: =D35-1 -> 46265 | G34: ='Indirect Costs'!C45 -> C1-29 | H34: =_xlfn.XLOOKUP(G34,'Indirect Costs'!C:C,'Indirect Costs'!D:D) -> RRHH
B35: 31 | C35: SEP 2026 Q1 | D35: 46266 | E35: =D36-1 -> 46280 | G35: ='Indirect Costs'!C46 -> C1-30 | H35: =_xlfn.XLOOKUP(G35,'Indirect Costs'!C:C,'Indirect Costs'!D:D) -> Contador
B36: 32 | C36: SEP 2026 Q2 | D36: 46281 | E36: =D37-1 -> 46295 | G36: ='Indirect Costs'!C47 -> C1-31 | H36: =_xlfn.XLOOKUP(G36,'Indirect Costs'!C:C,'Indirect Costs'!D:D) -> Jefe Almacen
B37: 33 | C37: OCT 2026 Q1 | D37: 46296 | E37: =D38-1 -> 46310 | G37: ='Indirect Costs'!C48 -> C1-32 | H37: =_xlfn.XLOOKUP(G37,'Indirect Costs'!C:C,'Indirect Costs'!D:D) -> Brigada Vigilancia armada (3 personas)
B38: 34 | C38: OCT 2026 Q2 | D38: 46311 | E38: =D39-1 -> 46326 | G38: ='Indirect Costs'!C49 -> C1-33 | H38: =_xlfn.XLOOKUP(G38,'Indirect Costs'!C:C,'Indirect Costs'!D:D) -> Brigada Vigilancia (3 personas)
B39: 35 | C39: NOV 2026 Q1 | D39: 46327 | E39: =D40-1 -> 46341 | G39: ='Indirect Costs'!C50 -> C1-34 | H39: =_xlfn.XLOOKUP(G39,'Indirect Costs'!C:C,'Indirect Costs'!D:D) -> Limpieza
B40: 36 | C40: NOV 2026 Q2 | D40: 46342 | E40: =D41-1 -> 46356 | G40: ='Indirect Costs'!C51 -> C1-35 | H40: =_xlfn.XLOOKUP(G40,'Indirect Costs'!C:C,'Indirect Costs'!D:D) -> Chófer transporte personal
B41: 37 | C41: DIC 2026 Q1 | D41: 46357 | E41: =D42-1 -> 46371 | G41: ='Indirect Costs'!C52 -> C2 | H41: =_xlfn.XLOOKUP(G41,'Indirect Costs'!C:C,'Indirect Costs'!D:D) -> EQUIPAMIENTO PARA PERSONAL DE OBRA
...

Sheet Costo Directo
F1: Costo supuesto
F2: Ofertado
D3: ='Resumen Ejecutivo'!C2 -> PROYECTO: | E3: =IF('Resumen Ejecutivo'!D2=0,"",'Resumen Ejecutivo'!D2) -> CONSTRUCCIÓN DE 50 PILAS DE CONCRETO ARMADO PARA PMI'S EN EL ESTADO DE TAMAULIPAS (TAMPICO Y MANTE) | I3: Tipo de Cambio (MXN / USD): | J3: 21
D4: ='Resumen Ejecutivo'!C3 -> CLIENTE: | E4: =IF('Resumen Ejecutivo'!D3=0,"",'Resumen Ejecutivo'!D3) -> SYM KABAT
H5: ='Indirect Costs'!G4 -> MESES DE EJECUCIÓN : | J5: 1
H6: Long. total (m) | L6: =L10/2 -> 534307.44 | N6: =N10/2 -> 26254.52 | P6: =P10/2 -> 55107.979 | R6: =R10/2 -> 35442.074
H7: Diesel | J7: =24/1.16 -> 20.689655
L8: PREVISION
C9: Costo Mensual | D9: C. Imp. | E9: - | F9: - | G9: - | H9: Costo/ml | I9: Costo Total Previsto | L9: JUN 2025 Q1 | M9: JUN 2025 Q2 | N9: JUL 2025 Q1 | O9: JUL 2025 Q2 | P9: AGO 2025 Q1 | Q9: AGO 2025 Q2 | R9: SEP 2025 Q1 | S9: SEP 2025 Q2 | T9: OCT 2025 Q1 | U9: OCT 2025 Q2 | V9: NOV 2025 Q1 | W9: NOV 2025 Q2 | X9: DIC 2025 Q1 | Y9: DIC 2025 Q2 | Z9: ENE 2026 Q1 | AA9: ENE 2026 Q2 | AB9: FEB 2026 Q1 | AC9: FEB 2026 Q2 | AD9: MAR 2026 Q1 | AE9: MAR 2026 Q2 | AF9: ABR 2026 Q1 | AG9: ABR 2026 Q2 | AH9: MAY 2026 Q1 | AI9: MAY 2026 Q2 | AJ9: JUN 2026 Q1 | AK9: JUN 2026 Q2 | AL9: JUL 2026 Q1 | AM9: JUL 2026 Q2 | AN9: AGO 2026 Q1 | AO9: AGO 2026 Q2 | AP9: SEP 2026 Q1 | AQ9: SEP 2026 Q2 | AR9: OCT 2026 Q1 | AS9: OCT 2026 Q2 | AT9: NOV 2026 Q1 | AU9: NOV 2026 Q2 | AV9: DIC 2026 Q1 | AW9: DIC 2026 Q2 | AX9: ENE 2027 Q1 | AY9: ENE 2027 Q2 | AZ9: FEB 2027 Q1 | BA9: FEB 2027 Q2 | BB9: MAR 2027 Q1 | BC9: MAR 2027 Q2 | BD9: ABR 2027 Q1 | BE9: ABR 2027 Q2 | BF9: MAY 2027 Q1 | BG9: MAY 2027 Q2 | BJ9: % Imputado | BK9: Imputado Acumulado | BM9: =L9 -> JUN 2025 Q1 | BN9: =M9 -> JUN 2025 Q2 | BO9: =N9 -> JUL 2025 Q1 | BP9: =O9 -> JUL 2025 Q2 | BQ9: =P9 -> AGO 2025 Q1 | BR9: =Q9 -> AGO 2025 Q2 | BS9: =R9 -> SEP 2025 Q1 | BT9: =S9 -> SEP 2025 Q2 | ... DH9: =BG9 -> MAY 2027 Q2
C10: =+J10/SUM(L14:BG14) -> 21.406521 | H10: =IFERROR(+J10/J6,0) -> 0 | J10: =SUBTOTAL(9,J13:J1194) -> 2445044.3 | L10: =SUBTOTAL(9,L13:L1194) -> 1068614.9 | M10: =SUBTOTAL(9,M13:M1194) -> 23088.077 | N10: =SUBTOTAL(9,N13:N1194) -> 52509.04 | O10: =SUBTOTAL(9,O13:O1194) -> 59263.977 | P10: =SUBTOTAL(9,P13:P1194) -> 110215.96 | Q10: =SUBTOTAL(9,Q13:Q1194) -> 23088.077 | R10: =SUBTOTAL(9,R13:R1194) -> 70884.147 | S10: =SUBTOTAL(9,S13:S1194) -> 48236.977 | ... BG10: =SUBTOTAL(9,BG13:BG1194) -> 0 | BJ10: =IFERROR(BK10/J10,0) -> 0.71941307 | BK10: =SUM(BM10:DH10) -> 1758996.8 | BM10: =SUBTOTAL(9,BM13:BM1194) -> 0 | BN10: =SUBTOTAL(9,BN13:BN1194) -> 104895.6 | BO10: =SUBTOTAL(9,BO13:BO1194) -> 253586.14 | BP10: =SUBTOTAL(9,BP13:BP1194) -> 716665.2 | BQ10: =SUBTOTAL(9,BQ13:BQ1194) -> 378985.49 | BR10: =SUBTOTAL(9,BR13:BR1194) -> 253319.92 | BS10: =SUBTOTAL(9,BS13:BS1194) -> 28344.49 | BT10: =SUBTOTAL(9,BT13:BT1194) -> 0 | ... DH10: =SUBTOTAL(9,DH13:DH1194) -> 0
A12: IMPRIMIR | C12: Estado | D12: C. Imp.
A13: =IF(J13>0,"Imprimir","") -> Imprimir | C13: MANTE | J13: =SUBTOTAL(9,J14:J247) -> 302381.54 | L13: =SUBTOTAL(9,L14:L248) -> 137132.47 | M13: =SUBTOTAL(9,M14:M248) -> 3128.3166 | N13: =SUBTOTAL(9,N14:N248) -> 6502.0466 | O13: =SUBTOTAL(9,O14:O248) -> 7970.0866 | P13: =SUBTOTAL(9,P14:P248) -> 14288.783 | Q13: =SUBTOTAL(9,Q14:Q248) -> 3128.3166 | R13: =SUBTOTAL(9,R14:R248) -> 8839.5966 | S13: =SUBTOTAL(9,S14:S248) -> 6470.1866 | ... BG13: =SUBTOTAL(9,BG14:BG248) -> 0 | BK13: =SUBTOTAL(9,BK14:BK247) -> 371644.91 | BM13: =SUBTOTAL(9,BM14:BM247) -> 0 | BN13: =SUBTOTAL(9,BN14:BN247) -> 0 | BO13: =SUBTOTAL(9,BO14:BO247) -> 44644.711 | BP13: =SUBTOTAL(9,BP14:BP247) -> 70050.608 | BQ13: =SUBTOTAL(9,BQ14:BQ247) -> 71831.784 | BR13: =SUBTOTAL(9,BR14:BR247) -> 185117.81 | BS13: =SUBTOTAL(9,BS14:BS247) -> 0 | BT13: =SUBTOTAL(9,BT14:BT247) -> 0 | ... DH13: =SUBTOTAL(9,DH14:DH247) -> 0
A14: =IF(J14>0,"Imprimir","") -> Imprimir | D14: P1 | E14: SUBCONTRATOS | J14: =SUBTOTAL(9,J17:J25) -> 114219.6 | L14: =SUMPRODUCT($J17:$J25,L17:L25) -> 43615.88 | M14: =SUMPRODUCT($J17:$J25,M17:M25) -> 0 | N14: =SUMPRODUCT($J17:$J25,N17:N25) -> 3373.48 | O14: =SUMPRODUCT($J17:$J25,O17:O25) -> 0 | P14: =SUMPRODUCT($J17:$J25,P17:P25) -> 3373.48 | Q14: =SUMPRODUCT($J17:$J25,Q17:Q25) -> 0 | R14: =SUMPRODUCT($J17:$J25,R17:R25) -> 5710.98 | S14: =SUMPRODUCT($J17:$J25,S17:S25) -> 0 | ... BG14: =SUMPRODUCT($J17:$J25,BG17:BG25) -> 0 | BJ14: =IFERROR(BK14/J14,0) -> 1.0405156 | BK14: =SUBTOTAL(9,BK15:BK25) -> 118847.27 | BM14: =SUBTOTAL(9,BM15:BM25) -> 0 | BN14: =SUBTOTAL(9,BN15:BN25) -> 0 | BO14: =SUBTOTAL(9,BO15:BO25) -> 0 | BP14: =SUBTOTAL(9,BP15:BP25) -> 2835.0013 | BQ14: =SUBTOTAL(9,BQ15:BQ25) -> 29455.531 | BR14: =SUBTOTAL(9,BR15:BR25) -> 86556.74 | BS14: =SUBTOTAL(9,BS15:BS25) -> 0 | BT14: =SUBTOTAL(9,BT15:BT25) -> 0 | ... DH14: =SUBTOTAL(9,DH15:DH25) -> 0
A15: =IF(J14>0,"Imprimir","") -> Imprimir | F15: Proveedor | G15: Costo Empresa | H15: Cantidad | I15: Meses | J15: Importe
A16: =IF(J16>0,"Imprimir","") -> Imprimir | J16: =SUBTOTAL(9,J17:J25) -> 114219.6
A17: =IF(J17="","",IF(J17=0,"","Imprimir")) -> Imprimir | D17: MAN-P1-1 | E17: COLADO DE CONCRETO CON TUBO TREMIE. TIRO DIRECTO | G17: 262 | H17: =Producción!G12*1 -> 17 | I17: =IF(E17>0,$J$5,"") -> 1 | J17: =IFERROR(G17*H17*I17,"") -> 4454 | L17: 0.3 | N17: 0.05 | P17: 0.05 | R17: 0.05 | T17: 0.05 | V17: 0.05 | X17: 0.05 | Z17: 0.05 | AB17: 0.05 | AD17: 0.05 | AF17: 0.05 | AH17: 0.05 | AJ17: 0.15 | BJ17: =IFERROR(BK17/J17,0) -> 0 | BK17: =SUM(BM17:DH17) -> 0 | BM17: =SUMIFS(Imput[[Importe Neto]:[Importe Neto]],Imput[[C. Imp.]:[C. Imp.]],$D17,Imput[[PERIODO Imp.]:[PERIODO Imp.]],BM$9) -> 0 | BN17: =SUMIFS(Imput[[Importe Neto]:[Importe Neto]],Imput[[C. Imp.]:[C. Imp.]],$D17,Imput[[PERIODO Imp.]:[PERIODO Imp.]],BN$9) -> 0 | BO17: =SUMIFS(Imput[[Importe Neto]:[Importe Neto]],Imput[[C. Imp.]:[C. Imp.]],$D17,Imput[[PERIODO Imp.]:[PERIODO Imp.]],BO$9) -> 0 | BP17: =SUMIFS(Imput[[Importe Neto]:[Importe Neto]],Imput[[C. Imp.]:[C. Imp.]],$D17,Imput[[PERIODO Imp.]:[PERIODO Imp.]],BP$9) -> 0 | BQ17: =SUMIFS(Imput[[Importe Neto]:[Importe Neto]],Imput[[C. Imp.]:[C. Imp.]],$D17,Imput[[PERIODO Imp.]:[PERIODO Imp.]],BQ$9) -> 0 | BR17: =SUMIFS(Imput[[Importe Neto]:[Importe Neto]],Imput[[C. Imp.]:[C. Imp.]],$D17,Imput[[PERIODO Imp.]:[PERIODO Imp.]],BR$9) -> 0 | BS17: =SUMIFS(Imput[[Importe Neto]:[Importe Neto]],Imput[[C. Imp.]:[C. Imp.]],$D17,Imput[[PERIODO Imp.]:[PERIODO Imp.]],BS$9) -> 0 | BT17: =SUMIFS(Imput[[Importe Neto]:[Importe Neto]],Imput[[C. Imp.]:[C. Imp.]],$D17,Imput[[PERIODO Imp.]:[PERIODO Imp.]],BT$9) -> 0 | ... DH17: =SUMIFS(Imput[[Importe Neto]:[Importe Neto]],Imput[[C. Imp.]:[C. Imp.]],$D17,Imput[[PERIODO Imp.]:[PERIODO Imp.]],DH$9) -> 0
A18: =IF(J18="","",IF(J18=0,"","Imprimir")) -> Imprimir | D18: MAN-P1-2 | E18: COLOCACIÓN DE ARMADO EN EXCAVACIÓN | G18: 170 | H18: =Producción!G12*1 -> 17 | I18: =IF(E18>0,$J$5,"") -> 1 | J18: =IFERROR(G18*H18*I18,"") -> 2890 | L18: 0.3 | N18: 0.05 | P18: 0.05 | R18: 0.05 | T18: 0.05 | V18: 0.05 | X18: 0.05 | Z18: 0.05 | AB18: 0.05 | AD18: 0.05 | AF18: 0.05 | AH18: 0.05 | AJ18: 0.15 | BJ18: =IFERROR(BK18/J18,0) -> 0 | BK18: =SUM(BM18:DH18) -> 0 | BM18: =SUMIFS(Imput[[Importe Neto]:[Importe Neto]],Imput[[C. Imp.]:[C. Imp.]],$D18,Imput[[PERIODO Imp.]:[PERIODO Imp.]],BM$9) -> 0 | BN18: =SUMIFS(Imput[[Importe Neto]:[Importe Neto]],Imput[[C. Imp.]:[C. Imp.]],$D18,Imput[[PERIODO Imp.]:[PERIODO Imp.]],BN$9) -> 0 | BO18: =SUMIFS(Imput[[Importe Neto]:[Importe Neto]],Imput[[C. Imp.]:[C. Imp.]],$D18,Imput[[PERIODO Imp.]:[PERIODO Imp.]],BO$9) -> 0 | BP18: =SUMIFS(Imput[[Importe Neto]:[Importe Neto]],Imput[[C. Imp.]:[C. Imp.]],$D18,Imput[[PERIODO Imp.]:[PERIODO Imp.]],BP$9) -> 0 | BQ18: =SUMIFS(Imput[[Importe Neto]:[Importe Neto]],Imput[[C. Imp.]:[C. Imp.]],$D18,Imput[[PERIODO Imp.]:[PERIODO Imp.]],BQ$9) -> 0 | BR18: =SUMIFS(Imput[[Importe Neto]:[Importe Neto]],Imput[[C. Imp.]:[C. Imp.]],$D18,Imput[[PERIODO Imp.]:[PERIODO Imp.]],BR$9) -> 0 | BS18: =SUMIFS(Imput[[Importe Neto]:[Importe Neto]],Imput[[C. Imp.]:[C. Imp.]],$D18,Imput[[PERIODO Imp.]:[PERIODO Imp.]],BS$9) -> 0 | BT18: =SUMIFS(Imput[[Importe Neto]:[Importe Neto]],Imput[[C. Imp.]:[C. Imp.]],$D18,Imput[[PERIODO Imp.]:[PERIODO Imp.]],BT$9) -> 0 | ... DH18: =SUMIFS(Imput[[Importe Neto]:[Importe Neto]],Imput[[C. Imp.]:[C. Imp.]],$D18,Imput[[PERIODO Imp.]:[PERIODO Imp.]],DH$9) -> 0
A19: =IF(J19="","",IF(J19=0,"","Imprimir")) -> Imprimir | D19: MAN-P1-3 | E19: FLETES DEL EQUIPO | G19: 80000 | H19: =Producción!G12*0.022 -> 0.374 | I19: =IF(E19>0,$J$5,"") -> 1 | J19: =IFERROR(G19*H19*I19,"") -> 29920 | L19: 0.3 | N19: 0.05 | P19: 0.05 | R19: 0.05 | T19: 0.05 | V19: 0.05 | X19: 0.05 | Z19: 0.05 | AB19: 0.05 | AD19: 0.05 | AF19: 0.05 | AH19: 0.05 | AJ19: 0.15 | BJ19: =IFERROR(BK19/J19,0) -> 0 | BK19: =SUM(BM19:DH19) -> 0 | BM19: =SUMIFS(Imput[[Importe Neto]:[Importe Neto]],Imput[[C. Imp.]:[C. Imp.]],$D19,Imput[[PERIODO Imp.]:[PERIODO Imp.]],BM$9) -> 0 | BN19: =SUMIFS(Imput[[Importe Neto]:[Importe Neto]],Imput[[C. Imp.]:[C. Imp.]],$D19,Imput[[PERIODO Imp.]:[PERIODO Imp.]],BN$9) -> 0 | BO19: =SUMIFS(Imput[[Importe Neto]:[Importe Neto]],Imput[[C. Imp.]:[C. Imp.]],$D19,Imput[[PERIODO Imp.]:[PERIODO Imp.]],BO$9) -> 0 | BP19: =SUMIFS(Imput[[Importe Neto]:[Importe Neto]],Imput[[C. Imp.]:[C. Imp.]],$D19,Imput[[PERIODO Imp.]:[PERIODO Imp.]],BP$9) -> 0 | BQ19: =SUMIFS(Imput[[Importe Neto]:[Importe Neto]],Imput[[C. Imp.]:[C. Imp.]],$D19,Imput[[PERIODO Imp.]:[PERIODO Imp.]],BQ$9) -> 0 | BR19: =SUMIFS(Imput[[Importe Neto]:[Importe Neto]],Imput[[C. Imp.]:[C. Imp.]],$D19,Imput[[PERIODO Imp.]:[PERIODO Imp.]],BR$9) -> 0 | BS19: =SUMIFS(Imput[[Importe Neto]:[Importe Neto]],Imput[[C. Imp.]:[C. Imp.]],$D19,Imput[[PERIODO Imp.]:[PERIODO Imp.]],BS$9) -> 0 | BT19: =SUMIFS(Imput[[Importe Neto]:[Importe Neto]],Imput[[C. Imp.]:[C. Imp.]],$D19,Imput[[PERIODO Imp.]:[PERIODO Imp.]],BT$9) -> 0 | ... DH19: =SUMIFS(Imput[[Importe Neto]:[Importe Neto]],Imput[[C. Imp.]:[C. Imp.]],$D19,Imput[[PERIODO Imp.]:[PERIODO Imp.]],DH$9) -> 0
A20: =IF(J20="","",IF(J20=0,"","Imprimir")) -> Imprimir | D20: MAN-P1-4 | E20: HABILITADO DE ACERO CORRUGADO DE CUALQUIER DIÁMETRO | G20: 10 | H20: =Producción!G12*127.68 -> 2170.56 | I20: =IF(E20>0,$J$5,"") -> 1 | J20: =IFERROR(G20*H20*I20,"") -> 21705.6 | L20: 0.3 | N20: 0.05 | P20: 0.05 | R20: 0.05 | T20: 0.05 | V20: 0.05 | X20: 0.05 | Z20: 0.05 | AB20: 0.05 | AD20: 0.05 | AF20: 0.05 | AH20: 0.05 | AJ20: 0.15 | BJ20: =IFERROR(BK20/J20,0) -> 0 | BK20: =SUM(BM20:DH20) -> 0 | BM20: =SUMIFS(Imput[[Importe Neto]:[Importe Neto]],Imput[[C. Imp.]:[C. Imp.]],$D20,Imput[[PERIODO Imp.]:[PERIODO Imp.]],BM$9) -> 0 | BN20: =SUMIFS(Imput[[Importe Neto]:[Importe Neto]],Imput[[C. Imp.]:[C. Imp.]],$D20,Imput[[PERIODO Imp.]:[PERIODO Imp.]],BN$9) -> 0 | BO20: =SUMIFS(Imput[[Importe Neto]:[Importe Neto]],Imput[[C. Imp.]:[C. Imp.]],$D20,Imput[[PERIODO Imp.]:[PERIODO Imp.]],BO$9) -> 0 | BP20: =SUMIFS(Imput[[Importe Neto]:[Importe Neto]],Imput[[C. Imp.]:[C. Imp.]],$D20,Imput[[PERIODO Imp.]:[PERIODO Imp.]],BP$9) -> 0 | BQ20: =SUMIFS(Imput[[Importe Neto]:[Importe Neto]],Imput[[C. Imp.]:[C. Imp.]],$D20,Imput[[PERIODO Imp.]:[PERIODO Imp.]],BQ$9) -> 0 | BR20: =SUMIFS(Imput[[Importe Neto]:[Importe Neto]],Imput[[C. Imp.]:[C. Imp.]],$D20,Imput[[PERIODO Imp.]:[PERIODO Imp.]],BR$9) -> 0 | BS20: =SUMIFS(Imput[[Importe Neto]:[Importe Neto]],Imput[[C. Imp.]:[C. Imp.]],$D20,Imput[[PERIODO Imp.]:[PERIODO Imp.]],BS$9) -> 0 | BT20: =SUMIFS(Imput[[Importe Neto]:[Importe Neto]],Imput[[C. Imp.]:[C. Imp.]],$D20,Imput[[PERIODO Imp.]:[PERIODO Imp.]],BT$9) -> 0 | ... DH20: =SUMIFS(Imput[[Importe Neto]:[Importe Neto]],Imput[[C. Imp.]:[C. Imp.]],$D20,Imput[[PERIODO Imp.]:[PERIODO Imp.]],DH$9) -> 0
A21: =IF(J21="","",IF(J21=0,"","Imprimir")) -> Imprimir | D21: MAN-P1-5 | E21: SUBCONTRATO DE EXCAVACIÓN POR MEDIOS MECÁNICOS | G21: 1100 | H21: =Producción!G12*2.5 -> 42.5 | I21: =IF(E21>0,$J$5,"") -> 1 | J21: =IFERROR(G21*H21*I21,"") -> 46750 | L21: 0.5 | R21: 0.05 | T21: 0.05 | V21: 0.05 | X21: 0.05 | Z21: 0.05 | AB21: 0.05 | AD21: 0.05 | AF21: 0.05 | AJ21: 0.1 | BJ21: =IFERROR(BK21/J21,0) -> 2.3001034 | BK21: =SUM(BM21:DH21) -> 107529.83 | BM21: =SUMIFS(Imput[[Importe Neto]:[Importe Neto]],Imput[[C. Imp.]:[C. Imp.]],$D21,Imput[[PERIODO Imp.]:[PERIODO Imp.]],BM$9) -> 0 | BN21: =SUMIFS(Imput[[Importe Neto]:[Importe Neto]],Imput[[C. Imp.]:[C. Imp.]],$D21,Imput[[PERIODO Imp.]:[PERIODO Imp.]],BN$9) -> 0 | BO21: =SUMIFS(Imput[[Importe Neto]:[Importe Neto]],Imput[[C. Imp.]:[C. Imp.]],$D21,Imput[[PERIODO Imp.]:[PERIODO Imp.]],BO$9) -> 0 | BP21: =SUMIFS(Imput[[Importe Neto]:[Importe Neto]],Imput[[C. Imp.]:[C. Imp.]],$D21,Imput[[PERIODO Imp.]:[PERIODO Imp.]],BP$9) -> 2445.0016 | BQ21: =SUMIFS(Imput[[Importe Neto]:[Importe Neto]],Imput[[C. Imp.]:[C. Imp.]],$D21,Imput[[PERIODO Imp.]:[PERIODO Imp.]],BQ$9) -> 29455.531 | BR21: =SUMIFS(Imput[[Importe Neto]:[Importe Neto]],Imput[[C. Imp.]:[C. Imp.]],$D21,Imput[[PERIODO Imp.]:[PERIODO Imp.]],BR$9) -> 75629.3 | BS21: =SUMIFS(Imput[[Importe Neto]:[Importe Neto]],Imput[[C. Imp.]:[C. Imp.]],$D21,Imput[[PERIODO Imp.]:[PERIODO Imp.]],BS$9) -> 0 | BT21: =SUMIFS(Imput[[Importe Neto]:[Importe Neto]],Imput[[C. Imp.]:[C. Imp.]],$D21,Imput[[PERIODO Imp.]:[PERIODO Imp.]],BT$9) -> 0 | ... DH21: =SUMIFS(Imput[[Importe Neto]:[Importe Neto]],Imput[[C. Imp.]:[C. Imp.]],$D21,Imput[[PERIODO Imp.]:[PERIODO Imp.]],DH$9) -> 0
A22: =IF(J22="","",IF(J22=0,"","Imprimir")) -> Imprimir | D22: MAN-P1-6 | E22: SUBCONTRATO DE GROUT Y BANQUETA (lote 10 pilas) | G22: 5000 | H22: =Producción!G12*0.1 -> 1.7 | I22: =IF(E22>0,$J$5,"") -> 1 | J22: =IFERROR(G22*H22*I22,"") -> 8500 | L22: 0.3 | N22: 0.05 | P22: 0.05 | R22: 0.05 | T22: 0.05 | V22: 0.05 | X22: 0.05 | Z22: 0.05 | AB22: 0.05 | AD22: 0.05 | AF22: 0.05 | AH22: 0.05 | AJ22: 0.15 | BJ22: =IFERROR(BK22/J22,0) -> 1.3314635 | BK22: =SUM(BM22:DH22) -> 11317.44 | BM22: =SUMIFS(Imput[[Importe Neto]:[Importe Neto]],Imput[[C. Imp.]:[C. Imp.]],$D22,Imput[[PERIODO Imp.]:[PERIODO Imp.]],BM$9) -> 0 | BN22: =SUMIFS(Imput[[Importe Neto]:[Importe Neto]],Imput[[C. Imp.]:[C. Imp.]],$D22,Imput[[PERIODO Imp.]:[PERIODO Imp.]],BN$9) -> 0 | BO22: =SUMIFS(Imput[[Importe Neto]:[Importe Neto]],Imput[[C. Imp.]:[C. Imp.]],$D22,Imput[[PERIODO Imp.]:[PERIODO Imp.]],BO$9) -> 0 | BP22: =SUMIFS(Imput[[Importe Neto]:[Importe Neto]],Imput[[C. Imp.]:[C. Imp.]],$D22,Imput[[PERIODO Imp.]:[PERIODO Imp.]],BP$9) -> 389.99973 | BQ22: =SUMIFS(Imput[[Importe Neto]:[Importe Neto]],Imput[[C. Imp.]:[C. Imp.]],$D22,Imput[[PERIODO Imp.]:[PERIODO Imp.]],BQ$9) -> 0 | BR22: =SUMIFS(Imput[[Importe Neto]:[Importe Neto]],Imput[[C. Imp.]:[C. Imp.]],$D22,Imput[[PERIODO Imp.]:[PERIODO Imp.]],BR$9) -> 10927.44 | BS22: =SUMIFS(Imput[[Importe Neto]:[Importe Neto]],Imput[[C. Imp.]:[C. Imp.]],$D22,Imput[[PERIODO Imp.]:[PERIODO Imp.]],BS$9) -> 0 | BT22: =SUMIFS(Imput[[Importe Neto]:[Importe Neto]],Imput[[C. Imp.]:[C. Imp.]],$D22,Imput[[PERIODO Imp.]:[PERIODO Imp.]],BT$9) -> 0 | ... DH22: =SUMIFS(Imput[[Importe Neto]:[Importe Neto]],Imput[[C. Imp.]:[C. Imp.]],$D22,Imput[[PERIODO Imp.]:[PERIODO Imp.]],DH$9) -> 0
A23: =IF(J23="","",IF(J23=0,"","Imprimir")) | D23: MAN-P1-7 | I23: =IF(E23>0,$J$5,"") | J23: =IFERROR(G23*H23*I23,"") | BJ23: =IFERROR(BK23/J23,0) -> 0 | BK23: =SUM(BM23:DH23) -> 0 | BM23: =SUMIFS(Imput[[Importe Neto]:[Importe Neto]],Imput[[C. Imp.]:[C. Imp.]],$D23,Imput[[PERIODO Imp.]:[PERIODO Imp.]],BM$9) -> 0 | BN23: =SUMIFS(Imput[[Importe Neto]:[Importe Neto]],Imput[[C. Imp.]:[C. Imp.]],$D23,Imput[[PERIODO Imp.]:[PERIODO Imp.]],BN$9) -> 0 | BO23: =SUMIFS(Imput[[Importe Neto]:[Importe Neto]],Imput[[C. Imp.]:[C. Imp.]],$D23,Imput[[PERIODO Imp.]:[PERIODO Imp.]],BO$9) -> 0 | BP23: =SUMIFS(Imput[[Importe Neto]:[Importe Neto]],Imput[[C. Imp.]:[C. Imp.]],$D23,Imput[[PERIODO Imp.]:[PERIODO Imp.]],BP$9) -> 0 | BQ23: =SUMIFS(Imput[[Importe Neto]:[Importe Neto]],Imput[[C. Imp.]:[C. Imp.]],$D23,Imput[[PERIODO Imp.]:[PERIODO Imp.]],BQ$9) -> 0 | BR23: =SUMIFS(Imput[[Importe Neto]:[Importe Neto]],Imput[[C. Imp.]:[C. Imp.]],$D23,Imput[[PERIODO Imp.]:[PERIODO Imp.]],BR$9) -> 0 | BS23: =SUMIFS(Imput[[Importe Neto]:[Importe Neto]],Imput[[C. Imp.]:[C. Imp.]],$D23,Imput[[PERIODO Imp.]:[PERIODO Imp.]],BS$9) -> 0 | BT23: =SUMIFS(Imput[[Importe Neto]:[Importe Neto]],Imput[[C. Imp.]:[C. Imp.]],$D23,Imput[[PERIODO Imp.]:[PERIODO Imp.]],BT$9) -> 0 | ... DH23: =SUMIFS(Imput[[Importe Neto]:[Importe Neto]],Imput[[C. Imp.]:[C. Imp.]],$D23,Imput[[PERIODO Imp.]:[PERIODO Imp.]],DH$9) -> 0
